<?xml version="1.0" encoding="UTF-8"?>
<testsuite name="unittest.loader._FailedTest-20220307104324" tests="1" file="unittest/loader.py" time="0.002" timestamp="2022-03-07T10:43:24" failures="0" errors="1" skipped="0">
	<testcase classname="unittest.loader._FailedTest" name="flask_tests" time="0.002" timestamp="2022-03-07T10:43:24">
		<error type="ImportError" message="Failed to import test module: flask_tests
Traceback (most recent call last):
  File &quot;C:\Users\Johnny\AppData\Local\Programs\Python\Python310\lib\unittest\loader.py&quot;, line 154, in loadTestsFromName
    module = __import__(module_name)
  File &quot;c:\users\johnny\desktop\everything\school\cs 4800 software engineering\bronco-mates\src\unittest\python\flask_tests.py&quot;, line 3, in &lt;module&gt;
    from flask_app import create_app
ModuleNotFoundError: No module named 'flask_app'
"><![CDATA[Traceback (most recent call last):
  File "C:\Users\Johnny\AppData\Local\Programs\Python\Python310\lib\unittest\case.py", line 59, in testPartExecutor
    yield
  File "C:\Users\Johnny\AppData\Local\Programs\Python\Python310\lib\unittest\case.py", line 591, in run
    self._callTestMethod(testMethod)
  File "C:\Users\Johnny\AppData\Local\Programs\Python\Python310\lib\unittest\case.py", line 549, in _callTestMethod
    method()
  File "C:\Users\Johnny\AppData\Local\Programs\Python\Python310\lib\unittest\loader.py", line 34, in testFailure
    raise self._exception
ImportError: Failed to import test module: flask_tests
Traceback (most recent call last):
  File "C:\Users\Johnny\AppData\Local\Programs\Python\Python310\lib\unittest\loader.py", line 154, in loadTestsFromName
    module = __import__(module_name)
  File "c:\users\johnny\desktop\everything\school\cs 4800 software engineering\bronco-mates\src\unittest\python\flask_tests.py", line 3, in <module>
    from flask_app import create_app
ModuleNotFoundError: No module named 'flask_app'

]]></error>
	</testcase>
</testsuite>
